<?xml version="1.0" encoding="UTF-8"?>
<testng-results skipped="0" failed="1" total="1" passed="0">
  <reporter-output>
  </reporter-output>
  <suite name="Suite" duration-ms="16469" started-at="2025-02-21T05:37:24Z" finished-at="2025-02-21T05:37:41Z">
    <groups>
    </groups>
    <test name="Test" duration-ms="16469" started-at="2025-02-21T05:37:24Z" finished-at="2025-02-21T05:37:41Z">
      <class name="org.test.TestRunner">
        <test-method status="PASS" signature="setUp()[pri:0, instance:org.test.TestRunner@31dc339b]" name="setUp" is-config="true" duration-ms="10883" started-at="2025-02-21T11:07:25Z" finished-at="2025-02-21T11:07:35Z">
          <reporter-output>
          </reporter-output>
        </test-method> <!-- setUp -->
        <test-method status="FAIL" signature="search1(java.lang.String, java.lang.String)[pri:0, instance:org.test.TestRunner@31dc339b]" name="search1" duration-ms="4222" started-at="2025-02-21T11:07:35Z" finished-at="2025-02-21T11:07:40Z">
          <params>
            <param index="0">
              <value>
                <![CDATA[kevin]]>
              </value>
            </param>
            <param index="1">
              <value>
                <![CDATA[fra]]>
              </value>
            </param>
          </params>
          <exception class="java.lang.AssertionError">
            <message>
              <![CDATA[The following asserts failed:
	expected [Arun] but found [Kumar]]]>
            </message>
            <full-stacktrace>
              <![CDATA[java.lang.AssertionError: The following asserts failed:
	expected [Arun] but found [Kumar]
	at org.testng.asserts.SoftAssert.assertAll(SoftAssert.java:43)
	at org.test.TestRunner.search1(TestRunner.java:113)
	at sun.reflect.NativeMethodAccessorImpl.invoke0(Native Method)
	at sun.reflect.NativeMethodAccessorImpl.invoke(Unknown Source)
	at sun.reflect.DelegatingMethodAccessorImpl.invoke(Unknown Source)
	at java.lang.reflect.Method.invoke(Unknown Source)
	at org.testng.internal.MethodInvocationHelper.invokeMethod(MethodInvocationHelper.java:100)
	at org.testng.internal.Invoker.invokeMethod(Invoker.java:646)
	at org.testng.internal.Invoker.invokeTestMethod(Invoker.java:811)
	at org.testng.internal.Invoker.invokeTestMethods(Invoker.java:1129)
	at org.testng.internal.TestMethodWorker.invokeTestMethods(TestMethodWorker.java:129)
	at org.testng.internal.TestMethodWorker.run(TestMethodWorker.java:112)
	at org.testng.TestRunner.privateRun(TestRunner.java:746)
	at org.testng.TestRunner.run(TestRunner.java:600)
	at org.testng.SuiteRunner.runTest(SuiteRunner.java:366)
	at org.testng.SuiteRunner.runSequentially(SuiteRunner.java:361)
	at org.testng.SuiteRunner.privateRun(SuiteRunner.java:319)
	at org.testng.SuiteRunner.run(SuiteRunner.java:268)
	at org.testng.SuiteRunnerWorker.runSuite(SuiteRunnerWorker.java:52)
	at org.testng.SuiteRunnerWorker.run(SuiteRunnerWorker.java:86)
	at org.testng.TestNG.runSuitesSequentially(TestNG.java:1264)
	at org.testng.TestNG.runSuitesLocally(TestNG.java:1189)
	at org.testng.TestNG.runSuites(TestNG.java:1104)
	at org.testng.TestNG.run(TestNG.java:1076)
	at org.testng.remote.AbstractRemoteTestNG.run(AbstractRemoteTestNG.java:126)
	at org.testng.remote.RemoteTestNG.initAndRun(RemoteTestNG.java:152)
	at org.testng.remote.RemoteTestNG.main(RemoteTestNG.java:57)
]]>
            </full-stacktrace>
          </exception> <!-- java.lang.AssertionError -->
          <reporter-output>
          </reporter-output>
        </test-method> <!-- search1 -->
        <test-method status="PASS" signature="tearDown()[pri:0, instance:org.test.TestRunner@31dc339b]" name="tearDown" is-config="true" duration-ms="726" started-at="2025-02-21T11:07:40Z" finished-at="2025-02-21T11:07:41Z">
          <reporter-output>
          </reporter-output>
        </test-method> <!-- tearDown -->
      </class> <!-- org.test.TestRunner -->
    </test> <!-- Test -->
  </suite> <!-- Suite -->
</testng-results>
